<?xml version="1.0"?>
<!--
Copyright (c) 2017, Toyota Motor Corporation
All rights reserved.

Redistribution and use in source and binary forms, with or without
modification, are permitted provided that the following conditions are met:

 * Redistributions of source code must retain the above copyright notice,
   this list of conditions and the following disclaimer.
 * Redistributions in binary form must reproduce the above copyright
   notice, this list of conditions and the following disclaimer in the
   documentation and/or other materials provided with the distribution.
 * Neither the name of Toyota Motor Corporation nor the names of its
   contributors may be used to endorse or promote products derived from
   this software without specific prior written permission.

THIS SOFTWARE IS PROVIDED BY THE COPYRIGHT HOLDERS AND CONTRIBUTORS "AS IS"
AND ANY EXPRESS OR IMPLIED WARRANTIES, INCLUDING, BUT NOT LIMITED TO, THE
IMPLIED WARRANTIES OF MERCHANTABILITY AND FITNESS FOR A PARTICULAR PURPOSE
ARE DISCLAIMED. IN NO EVENT SHALL THE COPYRIGHT OWNER OR CONTRIBUTORS BE
LIABLE FOR ANY DIRECT, INDIRECT, INCIDENTAL, SPECIAL, EXEMPLARY, OR
CONSEQUENTIAL DAMAGES (INCLUDING, BUT NOT LIMITED TO, PROCUREMENT OF
SUBSTITUTE GOODS OR SERVICES; LOSS OF USE, DATA, OR PROFITS; OR BUSINESS
INTERRUPTION) HOWEVER CAUSED AND ON ANY THEORY OF LIABILITY, WHETHER IN
CONTRACT, STRICT LIABILITY, OR TORT (INCLUDING NEGLIGENCE OR OTHERWISE)
ARISING IN ANY WAY OUT OF THE USE OF THIS SOFTWARE, EVEN IF ADVISED OF THE
POSSIBILITY OF SUCH DAMAGE.
-->


<robot name="hsrb">

    <include filename="$(find hsr_description)/robots/hsrb4s.urdf.xacro" />

    <link name="odom"/>

    <joint name="odom_x" type="prismatic">
        <axis xyz="1.0 0.0 0.0" />
        <limit effort="1.0" velocity="0.1" lower="-10.0" upper="10.0" />
        <parent link="odom" />
        <child link="odom_x_link" />
    </joint>

     <link name="odom_x_link"/>

    <joint name="odom_y" type="prismatic">
        <axis xyz="0.0 1.0 0.0" />
        <limit effort="1.0" velocity="0.1" lower="-10.0" upper="10.0" />
        <parent link="odom_x_link" />
        <child link="odom_y_link" />
    </joint>

     <link name="odom_y_link"/>

    <joint name="odom_t" type="continuous">
        <axis xyz="0.0 0.0 1.0" />
        <limit effort="1.0" velocity="0.1"/>
        <parent link="odom_y_link" />
        <child link="odom_t_link" />
    </joint>

    <link name="odom_t_link"/>

    <joint name="hsrb" type="fixed">
        <parent link="odom_t_link" />
        <child link="base_footprint" />
    </joint>

</robot>

